DEBUG 2024-11-04 22:44:52,471 django.template base.py (line 933) _resolve_lookup Exception while resolving variable 'slug' in template 'a_post/home.html'.
Traceback (most recent call last):
  File "C:\Users\ksrdrel\Desktop\FUTUR\Django HTMX\venv\Lib\site-packages\django\template\base.py", line 883, in _resolve_lookup
    current = current[bit]
              ~~~~~~~^^^^^
TypeError: 'NoneType' object is not subscriptable

During handling of the above exception, another exception occurred:

Traceback (most recent call last):
  File "C:\Users\ksrdrel\Desktop\FUTUR\Django HTMX\venv\Lib\site-packages\django\template\base.py", line 893, in _resolve_lookup
    current = getattr(current, bit)
              ^^^^^^^^^^^^^^^^^^^^^
AttributeError: 'NoneType' object has no attribute 'slug'

During handling of the above exception, another exception occurred:

Traceback (most recent call last):
  File "C:\Users\ksrdrel\Desktop\FUTUR\Django HTMX\venv\Lib\site-packages\django\template\base.py", line 899, in _resolve_lookup
    current = current[int(bit)]
                      ^^^^^^^^
ValueError: invalid literal for int() with base 10: 'slug'

During handling of the above exception, another exception occurred:

Traceback (most recent call last):
  File "C:\Users\ksrdrel\Desktop\FUTUR\Django HTMX\venv\Lib\site-packages\django\template\base.py", line 906, in _resolve_lookup
    raise VariableDoesNotExist(
django.template.base.VariableDoesNotExist: Failed lookup for key [slug] in None
DEBUG 2024-11-04 22:44:52,474 django.template base.py (line 933) _resolve_lookup Exception while resolving variable 'slug' in template 'a_post/home.html'.
Traceback (most recent call last):
  File "C:\Users\ksrdrel\Desktop\FUTUR\Django HTMX\venv\Lib\site-packages\django\template\base.py", line 883, in _resolve_lookup
    current = current[bit]
              ~~~~~~~^^^^^
TypeError: 'NoneType' object is not subscriptable

During handling of the above exception, another exception occurred:

Traceback (most recent call last):
  File "C:\Users\ksrdrel\Desktop\FUTUR\Django HTMX\venv\Lib\site-packages\django\template\base.py", line 893, in _resolve_lookup
    current = getattr(current, bit)
              ^^^^^^^^^^^^^^^^^^^^^
AttributeError: 'NoneType' object has no attribute 'slug'

During handling of the above exception, another exception occurred:

Traceback (most recent call last):
  File "C:\Users\ksrdrel\Desktop\FUTUR\Django HTMX\venv\Lib\site-packages\django\template\base.py", line 899, in _resolve_lookup
    current = current[int(bit)]
                      ^^^^^^^^
ValueError: invalid literal for int() with base 10: 'slug'

During handling of the above exception, another exception occurred:

Traceback (most recent call last):
  File "C:\Users\ksrdrel\Desktop\FUTUR\Django HTMX\venv\Lib\site-packages\django\template\base.py", line 906, in _resolve_lookup
    raise VariableDoesNotExist(
django.template.base.VariableDoesNotExist: Failed lookup for key [slug] in None
DEBUG 2024-11-04 22:44:52,478 django.template base.py (line 933) _resolve_lookup Exception while resolving variable 'slug' in template 'a_post/home.html'.
Traceback (most recent call last):
  File "C:\Users\ksrdrel\Desktop\FUTUR\Django HTMX\venv\Lib\site-packages\django\template\base.py", line 883, in _resolve_lookup
    current = current[bit]
              ~~~~~~~^^^^^
TypeError: 'NoneType' object is not subscriptable

During handling of the above exception, another exception occurred:

Traceback (most recent call last):
  File "C:\Users\ksrdrel\Desktop\FUTUR\Django HTMX\venv\Lib\site-packages\django\template\base.py", line 893, in _resolve_lookup
    current = getattr(current, bit)
              ^^^^^^^^^^^^^^^^^^^^^
AttributeError: 'NoneType' object has no attribute 'slug'

During handling of the above exception, another exception occurred:

Traceback (most recent call last):
  File "C:\Users\ksrdrel\Desktop\FUTUR\Django HTMX\venv\Lib\site-packages\django\template\base.py", line 899, in _resolve_lookup
    current = current[int(bit)]
                      ^^^^^^^^
ValueError: invalid literal for int() with base 10: 'slug'

During handling of the above exception, another exception occurred:

Traceback (most recent call last):
  File "C:\Users\ksrdrel\Desktop\FUTUR\Django HTMX\venv\Lib\site-packages\django\template\base.py", line 906, in _resolve_lookup
    raise VariableDoesNotExist(
django.template.base.VariableDoesNotExist: Failed lookup for key [slug] in None
DEBUG 2024-11-04 22:44:52,482 django.template base.py (line 933) _resolve_lookup Exception while resolving variable 'slug' in template 'a_post/home.html'.
Traceback (most recent call last):
  File "C:\Users\ksrdrel\Desktop\FUTUR\Django HTMX\venv\Lib\site-packages\django\template\base.py", line 883, in _resolve_lookup
    current = current[bit]
              ~~~~~~~^^^^^
TypeError: 'NoneType' object is not subscriptable

During handling of the above exception, another exception occurred:

Traceback (most recent call last):
  File "C:\Users\ksrdrel\Desktop\FUTUR\Django HTMX\venv\Lib\site-packages\django\template\base.py", line 893, in _resolve_lookup
    current = getattr(current, bit)
              ^^^^^^^^^^^^^^^^^^^^^
AttributeError: 'NoneType' object has no attribute 'slug'

During handling of the above exception, another exception occurred:

Traceback (most recent call last):
  File "C:\Users\ksrdrel\Desktop\FUTUR\Django HTMX\venv\Lib\site-packages\django\template\base.py", line 899, in _resolve_lookup
    current = current[int(bit)]
                      ^^^^^^^^
ValueError: invalid literal for int() with base 10: 'slug'

During handling of the above exception, another exception occurred:

Traceback (most recent call last):
  File "C:\Users\ksrdrel\Desktop\FUTUR\Django HTMX\venv\Lib\site-packages\django\template\base.py", line 906, in _resolve_lookup
    raise VariableDoesNotExist(
django.template.base.VariableDoesNotExist: Failed lookup for key [slug] in None
DEBUG 2024-11-04 22:44:52,484 django.template base.py (line 933) _resolve_lookup Exception while resolving variable 'slug' in template 'a_post/home.html'.
Traceback (most recent call last):
  File "C:\Users\ksrdrel\Desktop\FUTUR\Django HTMX\venv\Lib\site-packages\django\template\base.py", line 883, in _resolve_lookup
    current = current[bit]
              ~~~~~~~^^^^^
TypeError: 'NoneType' object is not subscriptable

During handling of the above exception, another exception occurred:

Traceback (most recent call last):
  File "C:\Users\ksrdrel\Desktop\FUTUR\Django HTMX\venv\Lib\site-packages\django\template\base.py", line 893, in _resolve_lookup
    current = getattr(current, bit)
              ^^^^^^^^^^^^^^^^^^^^^
AttributeError: 'NoneType' object has no attribute 'slug'

During handling of the above exception, another exception occurred:

Traceback (most recent call last):
  File "C:\Users\ksrdrel\Desktop\FUTUR\Django HTMX\venv\Lib\site-packages\django\template\base.py", line 899, in _resolve_lookup
    current = current[int(bit)]
                      ^^^^^^^^
ValueError: invalid literal for int() with base 10: 'slug'

During handling of the above exception, another exception occurred:

Traceback (most recent call last):
  File "C:\Users\ksrdrel\Desktop\FUTUR\Django HTMX\venv\Lib\site-packages\django\template\base.py", line 906, in _resolve_lookup
    raise VariableDoesNotExist(
django.template.base.VariableDoesNotExist: Failed lookup for key [slug] in None
DEBUG 2024-11-04 22:44:52,487 django.template base.py (line 933) _resolve_lookup Exception while resolving variable 'slug' in template 'a_post/home.html'.
Traceback (most recent call last):
  File "C:\Users\ksrdrel\Desktop\FUTUR\Django HTMX\venv\Lib\site-packages\django\template\base.py", line 883, in _resolve_lookup
    current = current[bit]
              ~~~~~~~^^^^^
TypeError: 'NoneType' object is not subscriptable

During handling of the above exception, another exception occurred:

Traceback (most recent call last):
  File "C:\Users\ksrdrel\Desktop\FUTUR\Django HTMX\venv\Lib\site-packages\django\template\base.py", line 893, in _resolve_lookup
    current = getattr(current, bit)
              ^^^^^^^^^^^^^^^^^^^^^
AttributeError: 'NoneType' object has no attribute 'slug'

During handling of the above exception, another exception occurred:

Traceback (most recent call last):
  File "C:\Users\ksrdrel\Desktop\FUTUR\Django HTMX\venv\Lib\site-packages\django\template\base.py", line 899, in _resolve_lookup
    current = current[int(bit)]
                      ^^^^^^^^
ValueError: invalid literal for int() with base 10: 'slug'

During handling of the above exception, another exception occurred:

Traceback (most recent call last):
  File "C:\Users\ksrdrel\Desktop\FUTUR\Django HTMX\venv\Lib\site-packages\django\template\base.py", line 906, in _resolve_lookup
    raise VariableDoesNotExist(
django.template.base.VariableDoesNotExist: Failed lookup for key [slug] in None
DEBUG 2024-11-04 22:44:52,490 django.template base.py (line 933) _resolve_lookup Exception while resolving variable 'slug' in template 'a_post/home.html'.
Traceback (most recent call last):
  File "C:\Users\ksrdrel\Desktop\FUTUR\Django HTMX\venv\Lib\site-packages\django\template\base.py", line 883, in _resolve_lookup
    current = current[bit]
              ~~~~~~~^^^^^
TypeError: 'NoneType' object is not subscriptable

During handling of the above exception, another exception occurred:

Traceback (most recent call last):
  File "C:\Users\ksrdrel\Desktop\FUTUR\Django HTMX\venv\Lib\site-packages\django\template\base.py", line 893, in _resolve_lookup
    current = getattr(current, bit)
              ^^^^^^^^^^^^^^^^^^^^^
AttributeError: 'NoneType' object has no attribute 'slug'

During handling of the above exception, another exception occurred:

Traceback (most recent call last):
  File "C:\Users\ksrdrel\Desktop\FUTUR\Django HTMX\venv\Lib\site-packages\django\template\base.py", line 899, in _resolve_lookup
    current = current[int(bit)]
                      ^^^^^^^^
ValueError: invalid literal for int() with base 10: 'slug'

During handling of the above exception, another exception occurred:

Traceback (most recent call last):
  File "C:\Users\ksrdrel\Desktop\FUTUR\Django HTMX\venv\Lib\site-packages\django\template\base.py", line 906, in _resolve_lookup
    raise VariableDoesNotExist(
django.template.base.VariableDoesNotExist: Failed lookup for key [slug] in None
DEBUG 2024-11-05 10:06:07,330 django.template base.py (line 933) _resolve_lookup Exception while resolving variable 'name' in template 'unknown'.
Traceback (most recent call last):
  File "C:\Users\ksrdrel\Desktop\FUTUR\Django HTMX\venv\Lib\site-packages\django\core\handlers\exception.py", line 55, in inner
    response = get_response(request)
               ^^^^^^^^^^^^^^^^^^^^^
  File "C:\Users\ksrdrel\Desktop\FUTUR\Django HTMX\venv\Lib\site-packages\django\core\handlers\base.py", line 181, in _get_response
    callback, callback_args, callback_kwargs = self.resolve_request(request)
                                               ^^^^^^^^^^^^^^^^^^^^^^^^^^^^^
  File "C:\Users\ksrdrel\Desktop\FUTUR\Django HTMX\venv\Lib\site-packages\django\core\handlers\base.py", line 313, in resolve_request
    resolver_match = resolver.resolve(request.path_info)
                     ^^^^^^^^^^^^^^^^^^^^^^^^^^^^^^^^^^^
  File "C:\Users\ksrdrel\Desktop\FUTUR\Django HTMX\venv\Lib\site-packages\django\urls\resolvers.py", line 705, in resolve
    raise Resolver404({"tried": tried, "path": new_path})
django.urls.exceptions.Resolver404: {'tried': [[<URLResolver <module 'debug_toolbar.urls' from 'C:\\Users\\ksrdrel\\Desktop\\FUTUR\\Django HTMX\\venv\\Lib\\site-packages\\debug_toolbar\\urls.py'> (djdt:djdt) '__debug__/'>], [<URLResolver <URLPattern list> (admin:admin) 'admin/'>], [<URLResolver <module 'allauth.urls' from 'C:\\Users\\ksrdrel\\Desktop\\FUTUR\\Django HTMX\\venv\\Lib\\site-packages\\allauth\\urls.py'> (None:None) 'accounts/'>], [<URLResolver <module 'a_post.urls' from 'C:\\Users\\ksrdrel\\Desktop\\FUTUR\\Django HTMX\\a_post\\urls.py'> (None:None) ''>, <URLPattern '' [name='home']>], [<URLResolver <module 'a_post.urls' from 'C:\\Users\\ksrdrel\\Desktop\\FUTUR\\Django HTMX\\a_post\\urls.py'> (None:None) ''>, <URLPattern 'category/<str:tag>/' [name='category']>], [<URLResolver <module 'a_post.urls' from 'C:\\Users\\ksrdrel\\Desktop\\FUTUR\\Django HTMX\\a_post\\urls.py'> (None:None) ''>, <URLPattern 'post/create/' [name='post-create']>], [<URLResolver <module 'a_post.urls' from 'C:\\Users\\ksrdrel\\Desktop\\FUTUR\\Django HTMX\\a_post\\urls.py'> (None:None) ''>, <URLPattern 'post/delete/<uuid:pk>/' [name='post-delete']>], [<URLResolver <module 'a_post.urls' from 'C:\\Users\\ksrdrel\\Desktop\\FUTUR\\Django HTMX\\a_post\\urls.py'> (None:None) ''>, <URLPattern 'post/edit/<uuid:pk>/' [name='post-edit']>], [<URLResolver <module 'a_post.urls' from 'C:\\Users\\ksrdrel\\Desktop\\FUTUR\\Django HTMX\\a_post\\urls.py'> (None:None) ''>, <URLPattern 'post/<uuid:pk>/' [name='post-detail']>], [<URLResolver <module 'a_post.urls' from 'C:\\Users\\ksrdrel\\Desktop\\FUTUR\\Django HTMX\\a_post\\urls.py'> (None:None) ''>, <URLPattern 'post/<uuid:pk>/like/' [name='like-post']>], [<URLResolver <module 'a_post.urls' from 'C:\\Users\\ksrdrel\\Desktop\\FUTUR\\Django HTMX\\a_post\\urls.py'> (None:None) ''>, <URLPattern 'comment-sent/<uuid:pk>/' [name='comment-sent']>], [<URLResolver <module 'a_post.urls' from 'C:\\Users\\ksrdrel\\Desktop\\FUTUR\\Django HTMX\\a_post\\urls.py'> (None:None) ''>, <URLPattern 'comment/like/<uuid:pk>/' [name='like-comment']>], [<URLResolver <module 'a_post.urls' from 'C:\\Users\\ksrdrel\\Desktop\\FUTUR\\Django HTMX\\a_post\\urls.py'> (None:None) ''>, <URLPattern 'comment-delete/<uuid:pk>/' [name='comment-delete']>], [<URLResolver <module 'a_post.urls' from 'C:\\Users\\ksrdrel\\Desktop\\FUTUR\\Django HTMX\\a_post\\urls.py'> (None:None) ''>, <URLPattern 'comment-reply-sent/<uuid:pk>/' [name='comment-reply-sent']>], [<URLResolver <module 'a_post.urls' from 'C:\\Users\\ksrdrel\\Desktop\\FUTUR\\Django HTMX\\a_post\\urls.py'> (None:None) ''>, <URLPattern 'comment-reply/like/<uuid:pk>/' [name='like-comment-reply']>], [<URLResolver <module 'a_post.urls' from 'C:\\Users\\ksrdrel\\Desktop\\FUTUR\\Django HTMX\\a_post\\urls.py'> (None:None) ''>, <URLPattern 'comment-reply-delete/<uuid:pk>/' [name='comment-reply-delete']>], [<URLResolver <module 'a_users.urls' from 'C:\\Users\\ksrdrel\\Desktop\\FUTUR\\Django HTMX\\a_users\\urls.py'> (None:None) 'profile/'>], [<URLPattern '^media/(?P<path>.*)$'>]], 'path': 'swagger/'}

During handling of the above exception, another exception occurred:

Traceback (most recent call last):
  File "C:\Users\ksrdrel\Desktop\FUTUR\Django HTMX\venv\Lib\site-packages\django\template\base.py", line 883, in _resolve_lookup
    current = current[bit]
              ~~~~~~~^^^^^
TypeError: 'URLResolver' object is not subscriptable

During handling of the above exception, another exception occurred:

Traceback (most recent call last):
  File "C:\Users\ksrdrel\Desktop\FUTUR\Django HTMX\venv\Lib\site-packages\django\template\base.py", line 893, in _resolve_lookup
    current = getattr(current, bit)
              ^^^^^^^^^^^^^^^^^^^^^
AttributeError: 'URLResolver' object has no attribute 'name'

During handling of the above exception, another exception occurred:

Traceback (most recent call last):
  File "C:\Users\ksrdrel\Desktop\FUTUR\Django HTMX\venv\Lib\site-packages\django\template\base.py", line 899, in _resolve_lookup
    current = current[int(bit)]
                      ^^^^^^^^
ValueError: invalid literal for int() with base 10: 'name'

During handling of the above exception, another exception occurred:

Traceback (most recent call last):
  File "C:\Users\ksrdrel\Desktop\FUTUR\Django HTMX\venv\Lib\site-packages\django\template\base.py", line 906, in _resolve_lookup
    raise VariableDoesNotExist(
django.template.base.VariableDoesNotExist: Failed lookup for key [name] in <URLResolver <module 'debug_toolbar.urls' from 'C:\\Users\\ksrdrel\\Desktop\\FUTUR\\Django HTMX\\venv\\Lib\\site-packages\\debug_toolbar\\urls.py'> (djdt:djdt) '__debug__/'>
DEBUG 2024-11-05 10:06:07,341 django.template base.py (line 933) _resolve_lookup Exception while resolving variable 'name' in template 'unknown'.
Traceback (most recent call last):
  File "C:\Users\ksrdrel\Desktop\FUTUR\Django HTMX\venv\Lib\site-packages\django\core\handlers\exception.py", line 55, in inner
    response = get_response(request)
               ^^^^^^^^^^^^^^^^^^^^^
  File "C:\Users\ksrdrel\Desktop\FUTUR\Django HTMX\venv\Lib\site-packages\django\core\handlers\base.py", line 181, in _get_response
    callback, callback_args, callback_kwargs = self.resolve_request(request)
                                               ^^^^^^^^^^^^^^^^^^^^^^^^^^^^^
  File "C:\Users\ksrdrel\Desktop\FUTUR\Django HTMX\venv\Lib\site-packages\django\core\handlers\base.py", line 313, in resolve_request
    resolver_match = resolver.resolve(request.path_info)
                     ^^^^^^^^^^^^^^^^^^^^^^^^^^^^^^^^^^^
  File "C:\Users\ksrdrel\Desktop\FUTUR\Django HTMX\venv\Lib\site-packages\django\urls\resolvers.py", line 705, in resolve
    raise Resolver404({"tried": tried, "path": new_path})
django.urls.exceptions.Resolver404: {'tried': [[<URLResolver <module 'debug_toolbar.urls' from 'C:\\Users\\ksrdrel\\Desktop\\FUTUR\\Django HTMX\\venv\\Lib\\site-packages\\debug_toolbar\\urls.py'> (djdt:djdt) '__debug__/'>], [<URLResolver <URLPattern list> (admin:admin) 'admin/'>], [<URLResolver <module 'allauth.urls' from 'C:\\Users\\ksrdrel\\Desktop\\FUTUR\\Django HTMX\\venv\\Lib\\site-packages\\allauth\\urls.py'> (None:None) 'accounts/'>], [<URLResolver <module 'a_post.urls' from 'C:\\Users\\ksrdrel\\Desktop\\FUTUR\\Django HTMX\\a_post\\urls.py'> (None:None) ''>, <URLPattern '' [name='home']>], [<URLResolver <module 'a_post.urls' from 'C:\\Users\\ksrdrel\\Desktop\\FUTUR\\Django HTMX\\a_post\\urls.py'> (None:None) ''>, <URLPattern 'category/<str:tag>/' [name='category']>], [<URLResolver <module 'a_post.urls' from 'C:\\Users\\ksrdrel\\Desktop\\FUTUR\\Django HTMX\\a_post\\urls.py'> (None:None) ''>, <URLPattern 'post/create/' [name='post-create']>], [<URLResolver <module 'a_post.urls' from 'C:\\Users\\ksrdrel\\Desktop\\FUTUR\\Django HTMX\\a_post\\urls.py'> (None:None) ''>, <URLPattern 'post/delete/<uuid:pk>/' [name='post-delete']>], [<URLResolver <module 'a_post.urls' from 'C:\\Users\\ksrdrel\\Desktop\\FUTUR\\Django HTMX\\a_post\\urls.py'> (None:None) ''>, <URLPattern 'post/edit/<uuid:pk>/' [name='post-edit']>], [<URLResolver <module 'a_post.urls' from 'C:\\Users\\ksrdrel\\Desktop\\FUTUR\\Django HTMX\\a_post\\urls.py'> (None:None) ''>, <URLPattern 'post/<uuid:pk>/' [name='post-detail']>], [<URLResolver <module 'a_post.urls' from 'C:\\Users\\ksrdrel\\Desktop\\FUTUR\\Django HTMX\\a_post\\urls.py'> (None:None) ''>, <URLPattern 'post/<uuid:pk>/like/' [name='like-post']>], [<URLResolver <module 'a_post.urls' from 'C:\\Users\\ksrdrel\\Desktop\\FUTUR\\Django HTMX\\a_post\\urls.py'> (None:None) ''>, <URLPattern 'comment-sent/<uuid:pk>/' [name='comment-sent']>], [<URLResolver <module 'a_post.urls' from 'C:\\Users\\ksrdrel\\Desktop\\FUTUR\\Django HTMX\\a_post\\urls.py'> (None:None) ''>, <URLPattern 'comment/like/<uuid:pk>/' [name='like-comment']>], [<URLResolver <module 'a_post.urls' from 'C:\\Users\\ksrdrel\\Desktop\\FUTUR\\Django HTMX\\a_post\\urls.py'> (None:None) ''>, <URLPattern 'comment-delete/<uuid:pk>/' [name='comment-delete']>], [<URLResolver <module 'a_post.urls' from 'C:\\Users\\ksrdrel\\Desktop\\FUTUR\\Django HTMX\\a_post\\urls.py'> (None:None) ''>, <URLPattern 'comment-reply-sent/<uuid:pk>/' [name='comment-reply-sent']>], [<URLResolver <module 'a_post.urls' from 'C:\\Users\\ksrdrel\\Desktop\\FUTUR\\Django HTMX\\a_post\\urls.py'> (None:None) ''>, <URLPattern 'comment-reply/like/<uuid:pk>/' [name='like-comment-reply']>], [<URLResolver <module 'a_post.urls' from 'C:\\Users\\ksrdrel\\Desktop\\FUTUR\\Django HTMX\\a_post\\urls.py'> (None:None) ''>, <URLPattern 'comment-reply-delete/<uuid:pk>/' [name='comment-reply-delete']>], [<URLResolver <module 'a_users.urls' from 'C:\\Users\\ksrdrel\\Desktop\\FUTUR\\Django HTMX\\a_users\\urls.py'> (None:None) 'profile/'>], [<URLPattern '^media/(?P<path>.*)$'>]], 'path': 'swagger/'}

During handling of the above exception, another exception occurred:

Traceback (most recent call last):
  File "C:\Users\ksrdrel\Desktop\FUTUR\Django HTMX\venv\Lib\site-packages\django\template\base.py", line 883, in _resolve_lookup
    current = current[bit]
              ~~~~~~~^^^^^
TypeError: 'URLResolver' object is not subscriptable

During handling of the above exception, another exception occurred:

Traceback (most recent call last):
  File "C:\Users\ksrdrel\Desktop\FUTUR\Django HTMX\venv\Lib\site-packages\django\template\base.py", line 893, in _resolve_lookup
    current = getattr(current, bit)
              ^^^^^^^^^^^^^^^^^^^^^
AttributeError: 'URLResolver' object has no attribute 'name'

During handling of the above exception, another exception occurred:

Traceback (most recent call last):
  File "C:\Users\ksrdrel\Desktop\FUTUR\Django HTMX\venv\Lib\site-packages\django\template\base.py", line 899, in _resolve_lookup
    current = current[int(bit)]
                      ^^^^^^^^
ValueError: invalid literal for int() with base 10: 'name'

During handling of the above exception, another exception occurred:

Traceback (most recent call last):
  File "C:\Users\ksrdrel\Desktop\FUTUR\Django HTMX\venv\Lib\site-packages\django\template\base.py", line 906, in _resolve_lookup
    raise VariableDoesNotExist(
django.template.base.VariableDoesNotExist: Failed lookup for key [name] in <URLResolver <URLPattern list> (admin:admin) 'admin/'>
DEBUG 2024-11-05 10:06:07,345 django.template base.py (line 933) _resolve_lookup Exception while resolving variable 'name' in template 'unknown'.
Traceback (most recent call last):
  File "C:\Users\ksrdrel\Desktop\FUTUR\Django HTMX\venv\Lib\site-packages\django\core\handlers\exception.py", line 55, in inner
    response = get_response(request)
               ^^^^^^^^^^^^^^^^^^^^^
  File "C:\Users\ksrdrel\Desktop\FUTUR\Django HTMX\venv\Lib\site-packages\django\core\handlers\base.py", line 181, in _get_response
    callback, callback_args, callback_kwargs = self.resolve_request(request)
                                               ^^^^^^^^^^^^^^^^^^^^^^^^^^^^^
  File "C:\Users\ksrdrel\Desktop\FUTUR\Django HTMX\venv\Lib\site-packages\django\core\handlers\base.py", line 313, in resolve_request
    resolver_match = resolver.resolve(request.path_info)
                     ^^^^^^^^^^^^^^^^^^^^^^^^^^^^^^^^^^^
  File "C:\Users\ksrdrel\Desktop\FUTUR\Django HTMX\venv\Lib\site-packages\django\urls\resolvers.py", line 705, in resolve
    raise Resolver404({"tried": tried, "path": new_path})
django.urls.exceptions.Resolver404: {'tried': [[<URLResolver <module 'debug_toolbar.urls' from 'C:\\Users\\ksrdrel\\Desktop\\FUTUR\\Django HTMX\\venv\\Lib\\site-packages\\debug_toolbar\\urls.py'> (djdt:djdt) '__debug__/'>], [<URLResolver <URLPattern list> (admin:admin) 'admin/'>], [<URLResolver <module 'allauth.urls' from 'C:\\Users\\ksrdrel\\Desktop\\FUTUR\\Django HTMX\\venv\\Lib\\site-packages\\allauth\\urls.py'> (None:None) 'accounts/'>], [<URLResolver <module 'a_post.urls' from 'C:\\Users\\ksrdrel\\Desktop\\FUTUR\\Django HTMX\\a_post\\urls.py'> (None:None) ''>, <URLPattern '' [name='home']>], [<URLResolver <module 'a_post.urls' from 'C:\\Users\\ksrdrel\\Desktop\\FUTUR\\Django HTMX\\a_post\\urls.py'> (None:None) ''>, <URLPattern 'category/<str:tag>/' [name='category']>], [<URLResolver <module 'a_post.urls' from 'C:\\Users\\ksrdrel\\Desktop\\FUTUR\\Django HTMX\\a_post\\urls.py'> (None:None) ''>, <URLPattern 'post/create/' [name='post-create']>], [<URLResolver <module 'a_post.urls' from 'C:\\Users\\ksrdrel\\Desktop\\FUTUR\\Django HTMX\\a_post\\urls.py'> (None:None) ''>, <URLPattern 'post/delete/<uuid:pk>/' [name='post-delete']>], [<URLResolver <module 'a_post.urls' from 'C:\\Users\\ksrdrel\\Desktop\\FUTUR\\Django HTMX\\a_post\\urls.py'> (None:None) ''>, <URLPattern 'post/edit/<uuid:pk>/' [name='post-edit']>], [<URLResolver <module 'a_post.urls' from 'C:\\Users\\ksrdrel\\Desktop\\FUTUR\\Django HTMX\\a_post\\urls.py'> (None:None) ''>, <URLPattern 'post/<uuid:pk>/' [name='post-detail']>], [<URLResolver <module 'a_post.urls' from 'C:\\Users\\ksrdrel\\Desktop\\FUTUR\\Django HTMX\\a_post\\urls.py'> (None:None) ''>, <URLPattern 'post/<uuid:pk>/like/' [name='like-post']>], [<URLResolver <module 'a_post.urls' from 'C:\\Users\\ksrdrel\\Desktop\\FUTUR\\Django HTMX\\a_post\\urls.py'> (None:None) ''>, <URLPattern 'comment-sent/<uuid:pk>/' [name='comment-sent']>], [<URLResolver <module 'a_post.urls' from 'C:\\Users\\ksrdrel\\Desktop\\FUTUR\\Django HTMX\\a_post\\urls.py'> (None:None) ''>, <URLPattern 'comment/like/<uuid:pk>/' [name='like-comment']>], [<URLResolver <module 'a_post.urls' from 'C:\\Users\\ksrdrel\\Desktop\\FUTUR\\Django HTMX\\a_post\\urls.py'> (None:None) ''>, <URLPattern 'comment-delete/<uuid:pk>/' [name='comment-delete']>], [<URLResolver <module 'a_post.urls' from 'C:\\Users\\ksrdrel\\Desktop\\FUTUR\\Django HTMX\\a_post\\urls.py'> (None:None) ''>, <URLPattern 'comment-reply-sent/<uuid:pk>/' [name='comment-reply-sent']>], [<URLResolver <module 'a_post.urls' from 'C:\\Users\\ksrdrel\\Desktop\\FUTUR\\Django HTMX\\a_post\\urls.py'> (None:None) ''>, <URLPattern 'comment-reply/like/<uuid:pk>/' [name='like-comment-reply']>], [<URLResolver <module 'a_post.urls' from 'C:\\Users\\ksrdrel\\Desktop\\FUTUR\\Django HTMX\\a_post\\urls.py'> (None:None) ''>, <URLPattern 'comment-reply-delete/<uuid:pk>/' [name='comment-reply-delete']>], [<URLResolver <module 'a_users.urls' from 'C:\\Users\\ksrdrel\\Desktop\\FUTUR\\Django HTMX\\a_users\\urls.py'> (None:None) 'profile/'>], [<URLPattern '^media/(?P<path>.*)$'>]], 'path': 'swagger/'}

During handling of the above exception, another exception occurred:

Traceback (most recent call last):
  File "C:\Users\ksrdrel\Desktop\FUTUR\Django HTMX\venv\Lib\site-packages\django\template\base.py", line 883, in _resolve_lookup
    current = current[bit]
              ~~~~~~~^^^^^
TypeError: 'URLResolver' object is not subscriptable

During handling of the above exception, another exception occurred:

Traceback (most recent call last):
  File "C:\Users\ksrdrel\Desktop\FUTUR\Django HTMX\venv\Lib\site-packages\django\template\base.py", line 893, in _resolve_lookup
    current = getattr(current, bit)
              ^^^^^^^^^^^^^^^^^^^^^
AttributeError: 'URLResolver' object has no attribute 'name'

During handling of the above exception, another exception occurred:

Traceback (most recent call last):
  File "C:\Users\ksrdrel\Desktop\FUTUR\Django HTMX\venv\Lib\site-packages\django\template\base.py", line 899, in _resolve_lookup
    current = current[int(bit)]
                      ^^^^^^^^
ValueError: invalid literal for int() with base 10: 'name'

During handling of the above exception, another exception occurred:

Traceback (most recent call last):
  File "C:\Users\ksrdrel\Desktop\FUTUR\Django HTMX\venv\Lib\site-packages\django\template\base.py", line 906, in _resolve_lookup
    raise VariableDoesNotExist(
django.template.base.VariableDoesNotExist: Failed lookup for key [name] in <URLResolver <module 'allauth.urls' from 'C:\\Users\\ksrdrel\\Desktop\\FUTUR\\Django HTMX\\venv\\Lib\\site-packages\\allauth\\urls.py'> (None:None) 'accounts/'>
DEBUG 2024-11-05 10:06:07,352 django.template base.py (line 933) _resolve_lookup Exception while resolving variable 'name' in template 'unknown'.
Traceback (most recent call last):
  File "C:\Users\ksrdrel\Desktop\FUTUR\Django HTMX\venv\Lib\site-packages\django\core\handlers\exception.py", line 55, in inner
    response = get_response(request)
               ^^^^^^^^^^^^^^^^^^^^^
  File "C:\Users\ksrdrel\Desktop\FUTUR\Django HTMX\venv\Lib\site-packages\django\core\handlers\base.py", line 181, in _get_response
    callback, callback_args, callback_kwargs = self.resolve_request(request)
                                               ^^^^^^^^^^^^^^^^^^^^^^^^^^^^^
  File "C:\Users\ksrdrel\Desktop\FUTUR\Django HTMX\venv\Lib\site-packages\django\core\handlers\base.py", line 313, in resolve_request
    resolver_match = resolver.resolve(request.path_info)
                     ^^^^^^^^^^^^^^^^^^^^^^^^^^^^^^^^^^^
  File "C:\Users\ksrdrel\Desktop\FUTUR\Django HTMX\venv\Lib\site-packages\django\urls\resolvers.py", line 705, in resolve
    raise Resolver404({"tried": tried, "path": new_path})
django.urls.exceptions.Resolver404: {'tried': [[<URLResolver <module 'debug_toolbar.urls' from 'C:\\Users\\ksrdrel\\Desktop\\FUTUR\\Django HTMX\\venv\\Lib\\site-packages\\debug_toolbar\\urls.py'> (djdt:djdt) '__debug__/'>], [<URLResolver <URLPattern list> (admin:admin) 'admin/'>], [<URLResolver <module 'allauth.urls' from 'C:\\Users\\ksrdrel\\Desktop\\FUTUR\\Django HTMX\\venv\\Lib\\site-packages\\allauth\\urls.py'> (None:None) 'accounts/'>], [<URLResolver <module 'a_post.urls' from 'C:\\Users\\ksrdrel\\Desktop\\FUTUR\\Django HTMX\\a_post\\urls.py'> (None:None) ''>, <URLPattern '' [name='home']>], [<URLResolver <module 'a_post.urls' from 'C:\\Users\\ksrdrel\\Desktop\\FUTUR\\Django HTMX\\a_post\\urls.py'> (None:None) ''>, <URLPattern 'category/<str:tag>/' [name='category']>], [<URLResolver <module 'a_post.urls' from 'C:\\Users\\ksrdrel\\Desktop\\FUTUR\\Django HTMX\\a_post\\urls.py'> (None:None) ''>, <URLPattern 'post/create/' [name='post-create']>], [<URLResolver <module 'a_post.urls' from 'C:\\Users\\ksrdrel\\Desktop\\FUTUR\\Django HTMX\\a_post\\urls.py'> (None:None) ''>, <URLPattern 'post/delete/<uuid:pk>/' [name='post-delete']>], [<URLResolver <module 'a_post.urls' from 'C:\\Users\\ksrdrel\\Desktop\\FUTUR\\Django HTMX\\a_post\\urls.py'> (None:None) ''>, <URLPattern 'post/edit/<uuid:pk>/' [name='post-edit']>], [<URLResolver <module 'a_post.urls' from 'C:\\Users\\ksrdrel\\Desktop\\FUTUR\\Django HTMX\\a_post\\urls.py'> (None:None) ''>, <URLPattern 'post/<uuid:pk>/' [name='post-detail']>], [<URLResolver <module 'a_post.urls' from 'C:\\Users\\ksrdrel\\Desktop\\FUTUR\\Django HTMX\\a_post\\urls.py'> (None:None) ''>, <URLPattern 'post/<uuid:pk>/like/' [name='like-post']>], [<URLResolver <module 'a_post.urls' from 'C:\\Users\\ksrdrel\\Desktop\\FUTUR\\Django HTMX\\a_post\\urls.py'> (None:None) ''>, <URLPattern 'comment-sent/<uuid:pk>/' [name='comment-sent']>], [<URLResolver <module 'a_post.urls' from 'C:\\Users\\ksrdrel\\Desktop\\FUTUR\\Django HTMX\\a_post\\urls.py'> (None:None) ''>, <URLPattern 'comment/like/<uuid:pk>/' [name='like-comment']>], [<URLResolver <module 'a_post.urls' from 'C:\\Users\\ksrdrel\\Desktop\\FUTUR\\Django HTMX\\a_post\\urls.py'> (None:None) ''>, <URLPattern 'comment-delete/<uuid:pk>/' [name='comment-delete']>], [<URLResolver <module 'a_post.urls' from 'C:\\Users\\ksrdrel\\Desktop\\FUTUR\\Django HTMX\\a_post\\urls.py'> (None:None) ''>, <URLPattern 'comment-reply-sent/<uuid:pk>/' [name='comment-reply-sent']>], [<URLResolver <module 'a_post.urls' from 'C:\\Users\\ksrdrel\\Desktop\\FUTUR\\Django HTMX\\a_post\\urls.py'> (None:None) ''>, <URLPattern 'comment-reply/like/<uuid:pk>/' [name='like-comment-reply']>], [<URLResolver <module 'a_post.urls' from 'C:\\Users\\ksrdrel\\Desktop\\FUTUR\\Django HTMX\\a_post\\urls.py'> (None:None) ''>, <URLPattern 'comment-reply-delete/<uuid:pk>/' [name='comment-reply-delete']>], [<URLResolver <module 'a_users.urls' from 'C:\\Users\\ksrdrel\\Desktop\\FUTUR\\Django HTMX\\a_users\\urls.py'> (None:None) 'profile/'>], [<URLPattern '^media/(?P<path>.*)$'>]], 'path': 'swagger/'}

During handling of the above exception, another exception occurred:

Traceback (most recent call last):
  File "C:\Users\ksrdrel\Desktop\FUTUR\Django HTMX\venv\Lib\site-packages\django\template\base.py", line 883, in _resolve_lookup
    current = current[bit]
              ~~~~~~~^^^^^
TypeError: 'URLResolver' object is not subscriptable

During handling of the above exception, another exception occurred:

Traceback (most recent call last):
  File "C:\Users\ksrdrel\Desktop\FUTUR\Django HTMX\venv\Lib\site-packages\django\template\base.py", line 893, in _resolve_lookup
    current = getattr(current, bit)
              ^^^^^^^^^^^^^^^^^^^^^
AttributeError: 'URLResolver' object has no attribute 'name'

During handling of the above exception, another exception occurred:

Traceback (most recent call last):
  File "C:\Users\ksrdrel\Desktop\FUTUR\Django HTMX\venv\Lib\site-packages\django\template\base.py", line 899, in _resolve_lookup
    current = current[int(bit)]
                      ^^^^^^^^
ValueError: invalid literal for int() with base 10: 'name'

During handling of the above exception, another exception occurred:

Traceback (most recent call last):
  File "C:\Users\ksrdrel\Desktop\FUTUR\Django HTMX\venv\Lib\site-packages\django\template\base.py", line 906, in _resolve_lookup
    raise VariableDoesNotExist(
django.template.base.VariableDoesNotExist: Failed lookup for key [name] in <URLResolver <module 'a_users.urls' from 'C:\\Users\\ksrdrel\\Desktop\\FUTUR\\Django HTMX\\a_users\\urls.py'> (None:None) 'profile/'>
